ERROR:pygls.protocol:Failed to handle request 211 textDocument/hover work_done_token=None text_document=TextDocumentIdentifier(uri='file:///home/emamaker/Documents/Projects/TorPageViewer_Selenium_Docker/page_viewer.py') position=127:0
Traceback (most recent call last):
  File "/home/emamaker/.vscode-oss/extensions/ms-python.python-2022.0.1814523869/pythonFiles/lib/jedilsp/pygls/protocol.py", line 331, in _handle_request
    self._execute_request(msg_id, handler, params)
  File "/home/emamaker/.vscode-oss/extensions/ms-python.python-2022.0.1814523869/pythonFiles/lib/jedilsp/pygls/protocol.py", line 260, in _execute_request
    method_name, method_type, msg_id, handler(params))
  File "/home/emamaker/.vscode-oss/extensions/ms-python.python-2022.0.1814523869/pythonFiles/lib/jedilsp/jedi_language_server/server.py", line 352, in hover
    jedi_script.help(
  File "/home/emamaker/.vscode-oss/extensions/ms-python.python-2022.0.1814523869/pythonFiles/lib/jedilsp/jedi/api/helpers.py", line 484, in wrapper
    raise ValueError('`column` parameter (%d) is not in a valid range '
ValueError: `column` parameter (1) is not in a valid range (0-0) for line 128 ('\n').
[Error - 3:20:21 PM] Request textDocument/hover failed.
  Message: ValueError: `column` parameter (1) is not in a valid range (0-0) for line 128 ('\n').
  Code: -32602 
{'traceback': ['  File "/home/emamaker/.vscode-oss/extensions/ms-python.python-2022.0.1814523869/pythonFiles/lib/jedilsp/pygls/protocol.py", line 331, in _handle_request\n    self._execute_request(msg_id, handler, params)\n', '  File "/home/emamaker/.vscode-oss/extensions/ms-python.python-2022.0.1814523869/pythonFiles/lib/jedilsp/pygls/protocol.py", line 260, in _execute_request\n    method_name, method_type, msg_id, handler(params))\n', '  File "/home/emamaker/.vscode-oss/extensions/ms-python.python-2022.0.1814523869/pythonFiles/lib/jedilsp/jedi_language_server/server.py", line 352, in hover\n    jedi_script.help(\n', '  File "/home/emamaker/.vscode-oss/extensions/ms-python.python-2022.0.1814523869/pythonFiles/lib/jedilsp/jedi/api/helpers.py", line 484, in wrapper\n    raise ValueError(\'`column` parameter (%d) is not in a valid range \'\n']}
[Info  - 10:06:08 PM] Connection to server got closed. Server will restart.
